<?xml version="1.0" ?>

<robot name="atlas_skeleton">
    <link name="l_shoulder">
        <inertial>
            <mass value="3.45" />
            <origin xyz="0 0.048 0.084" rpy="0 -0 0" />
            <inertia ixx="0.011" ixy="0" ixz="0" iyy="0.009" iyz="-0.004" izz="0.004" />
        </inertial>
        <visual>
            <origin xyz="0 0 0" rpy="0 -0 0" />
            <geometry>
                <mesh filename="package://atlas_description/meshes_nv/l_shoulder.dae" scale="1 1 1" />
            </geometry>
        </visual>
        <collision>
            <origin xyz="0 0.048 0.084" rpy="0 -0 0" />
            <geometry>
                <mesh filename="package://atlas_description/meshes_nv/l_shoulder.stl" scale="1 1 1" />
            </geometry>
        </collision>
    </link>
    <link name="l_dfarm">
        <inertial>
            <mass value="3.388" />
            <origin xyz="0 -0.065 0" rpy="0 -0 0" />
            <inertia ixx="0.00656" ixy="0" ixz="0" iyy="0.00358" iyz="0" izz="0.00656" />
        </inertial>
        <visual>
            <origin xyz="0.0 -0.00 -0.00" rpy="-0.0 -0.0 -0.7" />
            <geometry>
                <mesh filename="package://atlas_description/meshes_nv/l_dfarm.dae" scale="1 1 1" />
            </geometry>
        </visual>
        <collision>
            <origin xyz="0.0 -0.00 -0.00" rpy="-0.0 -0.0 -0.7" />
            <geometry>
                <mesh filename="package://atlas_description/meshes_nv/l_dfarm.stl" scale="1 1 1" />
            </geometry>
        </collision>
    </link>
    <link name="l_foot">
        <inertial>
            <mass value="2.05" />
            <origin xyz="0.027 0 -0.067" rpy="0 -0 0" />
            <inertia ixx="0.002" ixy="0" ixz="0" iyy="0.007" iyz="0" izz="0.008" />
        </inertial>
        <visual>
            <origin xyz="0 0 0" rpy="0 -0 0" />
            <geometry>
                <mesh filename="package://atlas_description/meshes_nv/l_foot.dae" scale="1 1 1" />
            </geometry>
        </visual>
        <collision>
            <origin xyz="0 0 0" rpy="0 -0 0" />
            <geometry>
                <mesh filename="package://atlas_description/meshes_nv/foot.stl" scale="1 1 1" />
            </geometry>
        </collision>
    </link>
    <link name="l_hb_hand">
        <inertial>
            <mass value="2.509" />
            <origin xyz="0 0 0" rpy="0 -0 0" />
            <inertia ixx="0.00265" ixy="0" ixz="0" iyy="0.00446" iyz="0" izz="0.00446" />
        </inertial>
        <visual>
            <origin xyz="0.0 0.0 -0.03" rpy="0.0 -0.0 -0.7" />
            <geometry>
                <mesh filename="package://atlas_description/meshes_nv/l_hb_hand.dae" scale="1 1 1" />
            </geometry>
        </visual>
        <collision>
            <origin xyz="0.0 0.0 -0.0" rpy="0.0 -0.0 -0.7" />
            <geometry>
                <mesh filename="package://atlas_description/meshes_nv/l_hb_hand.stl" scale="1 1 1" />
            </geometry>
        </collision>
    </link>
    <link name="l_ufarm">
        <inertial>
            <mass value="2.509" />
            <origin xyz="0 0 0" rpy="0 -0 0" />
            <inertia ixx="0.00265" ixy="0" ixz="0" iyy="0.00446" iyz="0" izz="0.00446" />
        </inertial>
        <visual>
            <origin xyz="0 0 0" rpy="0.75 1.6 0.0" />
            <geometry>
                <mesh filename="package://atlas_description/meshes_nv/l_ufarm.dae" scale="1 1 1" />
            </geometry>
        </visual>
        <collision>
            <origin xyz="0 0 0" rpy="0.75 1.6 0.0" />
            <geometry>
                <mesh filename="package://atlas_description/meshes_nv/l_ufarm.stl" scale="1 1 1" />
            </geometry>
        </collision>
    </link>
    <link name="l_lglut">
        <inertial>
            <mass value="0.866" />
            <origin xyz="0.0133341 0.0170484 -0.0312052" rpy="0 -0 0" />
            <inertia ixx="0.000691326" ixy="-2.24344e-05" ixz="2.50508e-06" iyy="0.00126856" iyz="0.000137862" izz="0.00106487" />
        </inertial>
        <visual>
            <origin xyz="0 0 0" rpy="0 -0 0" />
            <geometry>
                <mesh filename="package://atlas_description/meshes_nv/l_lglut.dae" scale="1 1 1" />
            </geometry>
        </visual>
        <collision>
            <origin xyz="0 0 0" rpy="0 -0 0" />
            <geometry>
                <mesh filename="package://atlas_description/meshes_nv/l_lglut.stl" scale="1 1 1" />
            </geometry>
        </collision>
    </link>
    <link name="l_lleg">
        <inertial>
            <mass value="5.479" />
            <origin xyz="0.001 0 -0.187" rpy="0 -0 0" />
            <inertia ixx="0.077" ixy="0" ixz="-0.003" iyy="0.076" iyz="0" izz="0.01" />
        </inertial>
        <visual>
            <origin xyz="0 0 0" rpy="0 -0 0" />
            <geometry>
                <mesh filename="package://atlas_description/meshes_nv/l_lleg.dae" scale="1 1 1" />
            </geometry>
        </visual>
        <collision>
            <origin xyz="0 0 0" rpy="0 -0 0" />
            <geometry>
                <mesh filename="package://atlas_description/meshes_nv/l_lleg.stl" scale="1 1 1" />
            </geometry>
        </collision>
    </link>
  
    <link name="l_ankle">
        <inertial>
            <mass value="0.125" />
            <origin xyz="0 0 0" rpy="0 -0 0" />
            <inertia ixx="1.01674e-05" ixy="0" ixz="0" iyy="8.42775e-06" iyz="0" izz="1.30101e-05" />
        </inertial>
        <visual>
            <origin xyz="0 0 0" rpy="0 -0 0" />
            <geometry>
                <mesh filename="package://atlas_description/meshes_nv/ankle.dae" scale="1 1 1" />
            </geometry>
        </visual>
        <collision>
            <origin xyz="0 0 0" rpy="0 -0 0" />
            <geometry>
                <mesh filename="package://atlas_description/meshes_nv/ankle.stl" scale="1 1 1" />
            </geometry>
        </collision>
    </link>
    <link name="l_uarm">
        <inertial>
            <mass value="3.388" />
            <origin xyz="0 -0.065 0" rpy="0 -0 0" />
            <inertia ixx="0.00656" ixy="0" ixz="0" iyy="0.00358" iyz="0" izz="0.00656" />
        </inertial>
        <visual>
            <origin xyz="0 0 0" rpy="0 -0 0" />
            <geometry>
                <mesh filename="package://atlas_description/meshes_nv/l_uarm.dae" scale="1 1 1" />
            </geometry>
        </visual>
        <collision>
            <origin xyz="0 0 0" rpy="0 -0 0" />
            <geometry>
                <mesh filename="package://atlas_description/meshes_nv/l_uarm.stl" scale="1 1 1" />
            </geometry>
        </collision>
    </link>
    <link name="l_uglut">
        <inertial>
            <mass value="0.648" />
            <origin xyz="0.00529262 -0.00344732 0.00313046" rpy="0 -0 0" />
            <inertia ixx="0.00074276" ixy="-3.79607e-08" ixz="-2.79549e-05" iyy="0.000688179" iyz="-3.2735e-08" izz="0.00041242" />
        </inertial>
        <visual>
            <origin xyz="0 0 0" rpy="0 -0 0" />
            <geometry>
                <mesh filename="package://atlas_description/meshes_nv/l_uglut.dae" scale="1 1 1" />
            </geometry>
        </visual>
        <collision>
            <origin xyz="0 0 0" rpy="0 -0 0" />
            <geometry>
                <mesh filename="package://atlas_description/meshes_nv/l_uglut.stl" scale="1 1 1" />
            </geometry>
        </collision>
    </link>
    <link name="l_uleg">
        <inertial>
            <mass value="9.209" />
            <origin xyz="0 0 -0.21" rpy="0 -0 0" />
            <inertia ixx="0.09" ixy="0" ixz="0" iyy="0.09" iyz="0" izz="0.02" />
        </inertial>
        <visual>
            <origin xyz="0 0 0" rpy="0 -0 0" />
            <geometry>
                <mesh filename="package://atlas_description/meshes_nv/l_uleg.dae" scale="1 1 1" />
            </geometry>
        </visual>
        <collision>
            <origin xyz="0 0 0" rpy="0 -0 0" />
            <geometry>
                <mesh filename="package://atlas_description/meshes_nv/l_uleg.stl" scale="1 1 1" />
            </geometry>
        </collision>
    </link>
    <link name="ltorso">
        <inertial>
            <mass value="2.409" />
            <origin xyz="-0.0112984 -3.15366e-06 0.0746835" rpy="0 -0 0" />
            <inertia ixx="0.0039092" ixy="-5.04491e-08" ixz="-0.000342157" iyy="0.00341694" iyz="4.87119e-07" izz="0.00174492" />
        </inertial>
        <visual>
            <origin xyz="0 0 0" rpy="0 -0 0" />
            <geometry>
                <mesh filename="package://atlas_description/meshes_nv/ltorso.dae" scale="1 1 1" />
            </geometry>
        </visual>
        <collision>
            <origin xyz="0 0 0" rpy="0 -0 0" />
            <geometry>
                <mesh filename="package://atlas_description/meshes_v3/ltorso.stl" scale="1 1 1" />
            </geometry>
        </collision>
    </link>
    <link name="mtorso">
        <inertial>
            <mass value="0.69" />
            <origin xyz="-0.00816266 -0.0131245 0.0305974" rpy="0 -0 0" />
            <inertia ixx="0.000454181" ixy="-6.10764e-05" ixz="3.94009e-05" iyy="0.000483282" iyz="5.27463e-05" izz="0.000444215" />
        </inertial>
        <visual>
            <origin xyz="0 0 0" rpy="0 -0 0" />
            <geometry>
                <mesh filename="package://atlas_description/meshes_nv/mtorso.dae" scale="1 1 1" />
            </geometry>
        </visual>
        <collision>
            <origin xyz="0 0 0" rpy="0 -0 0" />
            <geometry>
                <mesh filename="package://atlas_description/meshes_nv/mtorso.stl" scale="1 1 1" />
            </geometry>
        </collision>
    </link>
    <link name="pelvis">
        <inertial>
            <mass value="17.882" />
            <origin xyz="0.0111 0 0.0271" rpy="0 -0 0" />
            <inertia ixx="0.1244" ixy="0.0008" ixz="-0.0007" iyy="0.0958" iyz="-0.0005" izz="0.1167" />
        </inertial>
        <visual>
            <origin xyz="0 0 0" rpy="0 -0 0" />
            <geometry>
                <mesh filename="package://atlas_description/meshes_nv/pelvis.dae" scale="1 1 1" />
            </geometry>
        </visual>
        <collision>
            <origin xyz="0 0 0" rpy="0 -0 0" />
            <geometry>
                <mesh filename="package://atlas_description/meshes_nv/pelvis.stl" scale="1 1 1" />
            </geometry>
        </collision>

    </link>
    <link name="utorso">
        <inertial>
            <mass value="3.45" />
            <origin xyz="0 -0.048 0.084" rpy="0 -0 0" />
            <inertia ixx="0.011" ixy="0" ixz="0" iyy="0.009" iyz="0.004" izz="0.004" />
        </inertial>
        <visual>
            <origin xyz="0 0 0" rpy="0 -0 0" />
            <geometry>
                <mesh filename="package://atlas_description/meshes_nv/utorso.dae" scale="1 1 1" />
            </geometry>
        </visual>
        <collision>
            <origin xyz="0 0 0" rpy="0 -0 0" />
            <geometry>
                <mesh filename="package://atlas_description/meshes_nv/utorso.stl" scale="1 1 1" />
            </geometry>
        </collision>
    </link>
    <link name="r_dfarm">
        <inertial>
            <mass value="3.388" />
            <origin xyz="0 0.065 0" rpy="0 -0 0" />
            <inertia ixx="0.00656" ixy="0" ixz="0" iyy="0.00358" iyz="0" izz="0.00656" />
        </inertial>
        <visual>
            <origin xyz="0.0 -0.00 -0.00" rpy="-0.0 -0.0 0.7" />
            <geometry>
                <mesh filename="package://atlas_description/meshes_nv/r_dfarm.dae" scale="1 1 1" />
            </geometry>
        </visual>
        <collision>
            <origin xyz="0.00 -0.00 -0.00" rpy="-0.0 -0.0 0.7" />
            <geometry>
                <mesh filename="package://atlas_description/meshes_nv/r_dfarm.stl" scale="1 1 1" />
            </geometry>
        </collision>
    </link>
    <link name="r_foot">
        <inertial>
            <mass value="2.05" />
            <origin xyz="0.027 0 -0.067" rpy="0 -0 0" />
            <inertia ixx="0.002" ixy="0" ixz="0" iyy="0.007" iyz="0" izz="0.008" />
        </inertial>
        <visual>
            <origin xyz="0 0 0" rpy="0 -0 0" />
            <geometry>
                <mesh filename="package://atlas_description/meshes_nv/r_foot.dae" scale="1 1 1" />
            </geometry>
        </visual>
        <collision>
            <origin xyz="0 0 0" rpy="0 -0 0" />
            <geometry>
                <mesh filename="package://atlas_description/meshes_nv/foot.stl" scale="1 1 1" />
            </geometry>
        </collision>
    </link>
    <link name="r_hb_hand">
        <inertial>
            <mass value="2.509" />
            <origin xyz="0 0 0" rpy="0 -0 0" />
            <inertia ixx="0.00265" ixy="0" ixz="0" iyy="0.00446" iyz="0" izz="0.00446" />
        </inertial>
        <visual>
            <origin xyz="0.0 0.0 -0.0" rpy="0.0 -0.0 0.7" />
            <geometry>
                <mesh filename="package://atlas_description/meshes_nv/r_hb_hand.dae" scale="1 1 1" />
            </geometry>
        </visual>
        <collision>
            <origin xyz="0.0 0.0 -0.0" rpy="0.0 -0.0 0.7" />
            <geometry>
                <mesh filename="package://atlas_description/meshes_nv/r_hb_hand.stl" scale="1 1 1" />
            </geometry>
        </collision>
    </link>
    <link name="r_ufarm">
        <inertial>
            <mass value="2.509" />
            <origin xyz="0 0 0" rpy="0 -0 0" />
            <inertia ixx="0.00265" ixy="0" ixz="0" iyy="0.00446" iyz="0" izz="0.00446" />
        </inertial>
        <visual>
            <origin xyz="0 0 -0.05" rpy="-0.75 1.5 0.0" />
            <geometry>
                <mesh filename="package://atlas_description/meshes_nv/r_ufarm.dae" scale="1 1 1" />
            </geometry>
        </visual>
        <collision>
            <origin xyz="0 0 0" rpy="-0.75 1.6 0.0" />
            <geometry>
                <mesh filename="package://atlas_description/meshes_nv/r_ufarm.stl" scale="1 1 1" />
            </geometry>
        </collision>
    </link>
    <link name="r_lglut">
        <inertial>
            <mass value="0.866" />
            <origin xyz="0.0133341 -0.0170484 -0.0312052" rpy="0 -0 0" />
            <inertia ixx="0.000691326" ixy="2.24344e-05" ixz="2.50508e-06" iyy="0.00126856" iyz="-0.000137862" izz="0.00106487" />
        </inertial>
        <visual>
            <!-- there appears to be a bug in the visuals provided, not aligned with the other left one in x-direction
            <origin xyz="0 0 0" rpy="0 -0 0" />
            -->
            <origin xyz="0.01 0 0" rpy="0 -0 0" />
            <geometry>
                <mesh filename="package://atlas_description/meshes_nv/r_lglut.dae" scale="1 1 1" />
            </geometry>
        </visual>
        <collision>
            <origin xyz="0.01 0 0" rpy="0 -0 0" />
            <geometry>
                <mesh filename="package://atlas_description/meshes_nv/r_lglut.stl" scale="1 1 1" />
            </geometry>
        </collision>
    </link>
    <link name="r_lleg">
        <inertial>
            <mass value="5.479" />
            <origin xyz="0.001 0 -0.187" rpy="0 -0 0" />
            <inertia ixx="0.077" ixy="-0" ixz="-0.003" iyy="0.076" iyz="-0" izz="0.01" />
        </inertial>
        <visual>
            <origin xyz="0 0 0" rpy="0 -0 0" />
            <geometry>
                <mesh filename="package://atlas_description/meshes_nv/r_lleg.dae" scale="1 1 1" />
            </geometry>
        </visual>
        <collision>
            <origin xyz="0 0 0" rpy="0 -0 0" />
            <geometry>
                <mesh filename="package://atlas_description/meshes_nv/r_lleg.stl" scale="1 1 1" />
            </geometry>
        </collision>
    </link>
    <link name="r_shoulder">
        <inertial>
            <mass value="3.012" />
            <origin xyz="0 0 0" rpy="0 -0 0" />
            <inertia ixx="0.00319" ixy="0" ixz="0" iyy="0.00583" iyz="0" izz="0.00583" />
        </inertial>
        <visual>
            <origin xyz="0 0 0" rpy="0 -0 0" />
            <geometry>
                <mesh filename="package://atlas_description/meshes_nv/r_shoulder.dae" scale="1 1 1" />
            </geometry>
        </visual>
        <collision>
            <origin xyz="0 0 0" rpy="0 -0 0" />
            <geometry>
                <mesh filename="package://atlas_description/meshes_nv/r_shoulder.stl" scale="1 1 1" />
            </geometry>
        </collision>
    </link>
    <link name="r_ankle">
        <inertial>
            <mass value="0.125" />
            <origin xyz="0 0 0" rpy="0 -0 0" />
            <inertia ixx="1.01674e-05" ixy="0" ixz="0" iyy="8.42775e-06" iyz="0" izz="1.30101e-05" />
        </inertial>
        <visual>
            <origin xyz="0 0 0" rpy="0 -0 0" />
            <geometry>
                <mesh filename="package://atlas_description/meshes_nv/ankle.dae" scale="1 1 1" />
            </geometry>
        </visual>
        <collision>
            <origin xyz="0 0 0" rpy="0 -0 0" />
            <geometry>
                <mesh filename="package://atlas_description/meshes_nv/ankle.stl" scale="1 1 1" />
            </geometry>
        </collision>
    </link>
    <link name="r_uarm">
        <inertial>
            <mass value="3.388" />
            <origin xyz="0 0.065 0" rpy="0 -0 0" />
            <inertia ixx="0.00656" ixy="0" ixz="0" iyy="0.00358" iyz="0" izz="0.00656" />
        </inertial>
        <visual>
            <origin xyz="0 0 0" rpy="0 -0 0" />
            <geometry>
                <mesh filename="package://atlas_description/meshes_nv/r_uarm.dae" scale="1 1 1" />
            </geometry>
        </visual>
        <collision>
            <origin xyz="0 0 0" rpy="0 -0 0" />
            <geometry>
                <mesh filename="package://atlas_description/meshes_nv/r_uarm.stl" scale="1 1 1" />
            </geometry>
        </collision>
    </link>
    <link name="r_uglut">
        <inertial>
            <mass value="0.648" />
            <origin xyz="0.00529262 0.00344732 0.00313046" rpy="0 -0 0" />
            <inertia ixx="0.00074276" ixy="3.79607e-08" ixz="-2.79549e-05" iyy="0.000688179" iyz="3.2735e-08" izz="0.00041242" />
        </inertial>
        <visual>
            <origin xyz="0 0 0" rpy="0 -0 0" />
            <geometry>
                <mesh filename="package://atlas_description/meshes_nv/r_uglut.dae" scale="1 1 1" />
            </geometry>
        </visual>
        <collision>
            <origin xyz="0 0 0" rpy="0 -0 0" />
            <geometry>
                <mesh filename="package://atlas_description/meshes_nv/r_uglut.stl" scale="1 1 1" />
            </geometry>
        </collision>
    </link>
    <link name="r_uleg">
        <inertial>
            <mass value="9.209" />
            <origin xyz="0 0 -0.21" rpy="0 -0 0" />
            <inertia ixx="0.09" ixy="0" ixz="0" iyy="0.09" iyz="0" izz="0.02" />
        </inertial>
        <visual>
            <origin xyz="0 0 0" rpy="0 -0 0" />
            <geometry>
                <mesh filename="package://atlas_description/meshes_nv/r_uleg.dae" scale="1 1 1" />
            </geometry>
        </visual>
        <collision>
            <origin xyz="0 0 0" rpy="0 -0 0" />
            <geometry>
                <mesh filename="package://atlas_description/meshes_nv/r_uleg.stl" scale="1 1 1" />
            </geometry>
        </collision>
    </link>
   
    <joint name="back_bkx" type="revolute">
        <origin xyz="0 0 -0.03" rpy="0 -0 0" />
        <axis xyz="1 0 0" />
        <parent link="mtorso" />
        <child link="utorso" />
        <dynamics damping="0.1" friction="0" />
        <limit effort="200" velocity="12" lower="-0.698132" upper="0.698132" />
        <safety_controller k_position="100" k_velocity="100" soft_lower_limit="-10.6981" soft_upper_limit="10.6981" />
    </joint>
    <joint name="back_bky" type="revolute">
        <origin xyz="0 0 0.16197" rpy="0 -0 0" />
        <axis xyz="0 1 0" />
        <parent link="ltorso" />
        <child link="mtorso" />
        <dynamics damping="0.1" friction="0" />
        <limit effort="206.843" velocity="12" lower="-0.610691" upper="0.438427" />
        <safety_controller k_position="100" k_velocity="100" soft_lower_limit="-10.6107" soft_upper_limit="10.4384" />
    </joint>
    <joint name="back_bkz" type="revolute">
        <origin xyz="-0.0125 0 0" rpy="0 -0 0" />
        <axis xyz="0 0 1" />
        <parent link="pelvis" />
        <child link="ltorso" />
        <dynamics damping="0.2" friction="0" />
        <limit effort="124.016" velocity="12" lower="-0.663225" upper="0.663225" />
        <safety_controller k_position="100" k_velocity="100" soft_lower_limit="-10.6632" soft_upper_limit="10.6632" />
    </joint>
    <joint name="l_arm_elx" type="revolute">
        <origin xyz="0.23 1.1 0.28" rpy="0 -0 0" />
        <axis xyz="0 0 1" />
        <parent link="l_uarm" />
        <child link="l_ufarm" />
        <dynamics damping="0.2" friction="0" />
        <limit effort="114" velocity="12" lower="-1.57" upper="0" />
        <safety_controller k_position="100" k_velocity="100" soft_lower_limit="-10" soft_upper_limit="12.3562" />
    </joint>
    <joint name="l_arm_ely" type="revolute">
        <origin xyz="0 0.43 0.12" rpy="0 -0 0" />
        <axis xyz="1 0 0" />
        <parent link="l_shoulder" />
        <child link="l_uarm" />
        <dynamics damping="0.1" friction="0" />
        <limit effort="114" velocity="12" lower="-1.57" upper="1.57" />
        <safety_controller k_position="100" k_velocity="100" soft_lower_limit="-10" soft_upper_limit="13.1416" />
    </joint>
    <joint name="l_arm_shx" type="revolute">
        <origin xyz="0.18 0.42 1.24" rpy="0 0.0 0.0" />
        <axis xyz="0 0.96 0.25" />
        <parent link="utorso" />
        <child link="l_shoulder" />
        <dynamics damping="0.1" friction="0" />
        <limit effort="170" velocity="12" lower="-1.5708" upper="1.5708" />
        <safety_controller k_position="100" k_velocity="100" soft_lower_limit="-11.5708" soft_upper_limit="11.5708" />
    </joint>

    <joint name="l_arm_wrx" type="revolute">
        <origin xyz="0.25 0.3 0.0" rpy="0 -0 0" />         
        <axis xyz="0 0 1" />
        <parent link="l_dfarm" />
        <child link="l_hb_hand" />
        <dynamics damping="0.1" friction="0" />
        <limit effort="60" velocity="12" lower="-1.1781" upper="1.1781" />
        <safety_controller k_position="100" k_velocity="100" soft_lower_limit="-11.1781" soft_upper_limit="11.1781" />
    </joint>
    <joint name="l_arm_wry" type="revolute">   <!--arm revolute-->
        <origin xyz="0.17 0.17 -0.01" rpy="0 -0 0" /> 
        <axis xyz="0.7 0.7 0.0" />
        <parent link="l_ufarm" />
        <child link="l_dfarm" />
        <dynamics damping="0.1" friction="0" />
        <limit effort="114" velocity="12" lower="0" upper="3.14159" />
        <safety_controller k_position="100" k_velocity="100" soft_lower_limit="-10" soft_upper_limit="13.1416" />
    </joint>
    <joint name="l_leg_akx" type="revolute">
        <origin xyz="0 0 -0.19" rpy="0 -0 0" />
        <axis xyz="0 1 0" />
        <parent link="l_ankle" />
        <child link="l_foot" />
        <dynamics damping="0.1" friction="0" />
        <limit effort="90" velocity="12" lower="-0.8" upper="0.8" />
        <safety_controller k_position="100" k_velocity="100" soft_lower_limit="-10.8" soft_upper_limit="10.8" />
    </joint>
    <joint name="l_leg_aky" type="revolute">
        <origin xyz="-0.15 0 -1.12" rpy="0 -0 0" />
        <axis xyz="1 0 0" />
        <parent link="l_lleg" />
        <child link="l_ankle" />
        <dynamics damping="0.1" friction="0" />
        <limit effort="700" velocity="12" lower="-1" upper="0.7" />
        <safety_controller k_position="100" k_velocity="100" soft_lower_limit="-11" soft_upper_limit="10.7" />
    </joint>
    <joint name="l_leg_hpx" type="revolute">
        <origin xyz="0 0.17 0" rpy="0 -0 0" />
        <axis xyz="1 0 0" />
        <parent link="l_uglut" />
        <child link="l_lglut" />
        <dynamics damping="0.1" friction="0" />
        <limit effort="180" velocity="12" lower="-0.523599" upper="0.523599" />
        <safety_controller k_position="100" k_velocity="100" soft_lower_limit="-10.5236" soft_upper_limit="10.5236" />
    </joint>
    <joint name="l_leg_hpy" type="revolute">
        <origin xyz="0.0 0.1 0.0" rpy="0 -0 0" />
        <axis xyz="0 1 0" />
        <parent link="l_lglut" />
        <child link="l_uleg" />
        <dynamics damping="0.2" friction="0" />
        <limit effort="260" velocity="12" lower="-1.72072" upper="0.524821" />
        <safety_controller k_position="100" k_velocity="100" soft_lower_limit="-11.7207" soft_upper_limit="10.5248" />
    </joint>
    <joint name="l_leg_hpz" type="revolute">
        <origin xyz="0 0.2 -0.32" rpy="0 -0 0" />
        <axis xyz="0 0 1" />
        <parent link="pelvis" />
        <child link="l_uglut" />
        <dynamics damping="0.1" friction="0" />
        <limit effort="110" velocity="12" lower="-0.174533" upper="1.22173" />
        <safety_controller k_position="100" k_velocity="100" soft_lower_limit="-10.1745" soft_upper_limit="11.2217" />
    </joint>
    <joint name="l_leg_kny" type="revolute">
        <origin xyz="0.17 0.19 -1.12" rpy="0 -0 0" />
        <axis xyz="0 1 0" />
        <parent link="l_uleg" />
        <child link="l_lleg" />
        <dynamics damping="0.2" friction="0" />
        <limit effort="220" velocity="12" lower="0" upper="2.38569" />
        <safety_controller k_position="100" k_velocity="100" soft_lower_limit="-10" soft_upper_limit="12.3857" />
    </joint>
    <joint name="r_arm_elx" type="revolute">
        <origin xyz="0.2 -1.09 0.24" rpy="0 -0 0" />
        <axis xyz="0 0 1" />
        <parent link="r_uarm" />
        <child link="r_ufarm" />
        <dynamics damping="0.2" friction="0" />
        <limit effort="114" velocity="12" lower="0." upper="1.57" />
        <safety_controller k_position="100" k_velocity="100" soft_lower_limit="-12.3562" soft_upper_limit="10" />
    </joint>
    <joint name="r_arm_ely" type="revolute">
        <origin xyz="0 -0.43 0.18" rpy="0 -0 0" />
        <axis xyz="1 0 0" />
        <parent link="r_shoulder" />
        <child link="r_uarm" />
        <dynamics damping="0.1" friction="0" />
        <limit effort="114" velocity="12" lower="-1.57" upper="1.57" />
        <safety_controller k_position="100" k_velocity="100" soft_lower_limit="-10" soft_upper_limit="13.1416" />
    </joint>
    <joint name="r_arm_shx" type="revolute">
        <origin xyz="0.18 -0.42 1.24" rpy="0 0.0 0.0" />
        <axis xyz="0 -0.96 0.25" />
        <parent link="utorso" />
        <child link="r_shoulder" />
        <dynamics damping="0.1" friction="0" />
        <limit effort="170" velocity="12" lower="-1.5708" upper="1.5708" />
        <safety_controller k_position="100" k_velocity="100" soft_lower_limit="-11.5708" soft_upper_limit="11.5708" />
    </joint>

    <joint name="r_arm_wrx" type="revolute">
        <origin xyz="0.25 -0.3 -0.0" rpy="0 -0 0" /> 
        <!--<axis xyz="0.40 -0.74 0.39" />-->
        <axis xyz="0 0 1" />
        <parent link="r_dfarm" />
        <child link="r_hb_hand" />
        <dynamics damping="0.1" friction="0" />
        <limit effort="60" velocity="12" lower="-1.1781" upper="1.1781" />
        <safety_controller k_position="100" k_velocity="100" soft_lower_limit="-11.1781" soft_upper_limit="11.1781" />
    </joint>
    <joint name="r_arm_wry" type="revolute">
        <origin xyz="0.17 -0.17 -0.01" rpy="0 -0 0" />
        <axis xyz="0.7 -0.7 0.0" />
        <parent link="r_ufarm" />
        <child link="r_dfarm" />
        <dynamics damping="0.1" friction="0" />
        <limit effort="114" velocity="12" lower="0" upper="3.14159" />
        <safety_controller k_position="100" k_velocity="100" soft_lower_limit="-10" soft_upper_limit="13.1416" />
    </joint>
    <joint name="r_leg_akx" type="revolute">
        <origin xyz="0 0 -0.17" rpy="0 -0 0" />
        <axis xyz="0 1 0" />
        <parent link="r_ankle" />
        <child link="r_foot" />
        <dynamics damping="0.1" friction="0" />
        <limit effort="90" velocity="12" lower="-0.8" upper="0.8" />
        <safety_controller k_position="100" k_velocity="100" soft_lower_limit="-10.8" soft_upper_limit="10.8" />
    </joint>
    <joint name="r_leg_aky" type="revolute">
        <origin xyz="-0.15 0 -1.15" rpy="0 -0 0" />
        <axis xyz="1 0 0" />
        <parent link="r_lleg" />
        <child link="r_ankle" />
        <dynamics damping="0.1" friction="0" />
        <limit effort="700" velocity="12" lower="-1" upper="0.7" />
        <safety_controller k_position="100" k_velocity="100" soft_lower_limit="-11" soft_upper_limit="10.7" />
    </joint>
    <joint name="r_leg_hpx" type="revolute">
        <origin xyz="0 -0.17 0" rpy="0 -0 0" />
        <axis xyz="1 0 0" />
        <parent link="r_uglut" />
        <child link="r_lglut" />
        <dynamics damping="0.1" friction="0" />
        <limit effort="180" velocity="12" lower="-0.523599" upper="0.523599" />
        <safety_controller k_position="100" k_velocity="100" soft_lower_limit="-10.5236" soft_upper_limit="10.5236" />
    </joint>
    <joint name="r_leg_hpy" type="revolute">
        <origin xyz="0.0 -0.1 0.0" rpy="0 -0 0" />
        <axis xyz="0 1 0" />
        <parent link="r_lglut" />
        <child link="r_uleg" />
        <dynamics damping="0.2" friction="0" />
        <limit effort="260" velocity="12" lower="-1.72072" upper="0.524821" />
        <safety_controller k_position="100" k_velocity="100" soft_lower_limit="-11.7207" soft_upper_limit="10.5248" />
    </joint>
    <joint name="r_leg_hpz" type="revolute">
        <origin xyz="0 -0.2 -0.32" rpy="0 -0 0" />
        <axis xyz="0 0 1" />
        <parent link="pelvis" />
        <child link="r_uglut" />
        <dynamics damping="0.1" friction="0" />
        <limit effort="110" velocity="12" lower="-1.22173" upper="0.174533" />
        <safety_controller k_position="100" k_velocity="100" soft_lower_limit="-11.2217" soft_upper_limit="10.1745" />
    </joint>
    <joint name="r_leg_kny" type="revolute">
        <origin xyz="0.15 -0.19 -1.12" rpy="0 -0 0" />
        <axis xyz="0 1 0" />
        <parent link="r_uleg" />
        <child link="r_lleg" />
        <dynamics damping="0.2" friction="0" />
        <limit effort="220" velocity="12" lower="0" upper="2.38569" />
        <safety_controller k_position="100" k_velocity="100" soft_lower_limit="-10" soft_upper_limit="12.3857" />
    </joint>

    <joint name="neck_ry" type="revolute">
        <origin xyz="0.21672 0 0.53796" rpy="0 -0 0" />
        <axis xyz="0 1 0" />
        <parent link="utorso" />
        <child link="head" />
        <dynamics damping="0.1" friction="0" />
        <limit effort="5" velocity="12" lower="-0.602139" upper="1.14494" />
        <safety_controller k_position="100" k_velocity="100" soft_lower_limit="-10.6021" soft_upper_limit="11.1449" />
    </joint>

  <!-- new situational awareness cameras -->
   <link name="r_situational_awareness_camera_link">
      <inertial>
        <mass value="0.1"/>
        <origin xyz="0 0 0"/>
        <inertia ixx="0.00001" ixy="0" ixz="0" iyy="0.00001" iyz="0" izz="0.00001"/>
      </inertial>
     <!-- <visual>
        <origin rpy="0 0 0" xyz="0 0 0"/>
        <geometry>
          <box size="0.01 0.01 0.01"/>
        </geometry>
      </visual> -->
    </link>

    <joint name="r_situational_awareness_camera_joint" type="fixed">
      <parent link="utorso"/>
      <child link="r_situational_awareness_camera_link"/> 
      <!-- if camera points x-forward, bottom towards front of robot, 15 degree yaw forwards from
           lateral (+y) view -->
     <origin xyz="0.216409 -0.121799 0.406759" rpy="1.57079633 0 -1.30899694"/>
    </joint>
    <joint name="r_situational_awareness_camera_optical_frame_joint" type="fixed">
      <origin xyz="0 0 0" rpy="-1.5708 0.0 -1.5708" />
      <parent link="r_situational_awareness_camera_link" />
      <child link="r_situational_awareness_camera_optical_frame"/>
    </joint>
    <link name="r_situational_awareness_camera_optical_frame"/>

    <link name="l_situational_awareness_camera_link">
      <inertial>
        <mass value="0.1"/>
        <origin xyz="0 0 0"/>
        <inertia ixx="0.00001" ixy="0" ixz="0" iyy="0.00001" iyz="0" izz="0.00001"/>
      </inertial>
      <!--<visual>
      <origin rpy="0 0 0" xyz="0 0 0"/>
        <geometry>
          <box size="0.01 0.01 0.01"/>
        </geometry> 
      </visual> -->
    </link>
    <joint name="l_situational_awareness_camera_joint" type="fixed">
      <parent link="utorso"/>
      <child link="l_situational_awareness_camera_link"/>
      <!-- if camera points x-forward, bottom towards front of robot, 15 degree yaw forwards from
           lateral (+y) view -->
    <origin xyz="0.216409 0.121799 0.406759" rpy="-1.57079633 0 1.30899694"/>
    </joint>
    <joint name="l_situational_awareness_camera_optical_frame_joint" type="fixed">
      <origin xyz="0 0 0" rpy="-1.5708 0.0 -1.5708" />
      <parent link="l_situational_awareness_camera_link" />
      <child link="l_situational_awareness_camera_optical_frame"/>
    </joint>
    <link name="l_situational_awareness_camera_optical_frame"/>

    <link name="rear_situational_awareness_camera_link">
      <inertial>
        <mass value="0.1"/>
        <origin xyz="0 0 0"/>
        <inertia ixx="0.00001" ixy="0" ixz="0" iyy="0.00001" iyz="0" izz="0.00001"/>
      </inertial>
      <!--<visual>
        <origin rpy="0 0 0" xyz="0 0 0"/>
        <geometry>
          <box size="0.01 0.01 0.01"/>
        </geometry>
      </visual>-->
    </link>
    <joint name="rear_situational_awareness_camera_joint" type="fixed">
      <parent link="utorso"/>
      <child link="rear_situational_awareness_camera_link"/> 
      <!-- if camera points towards -X direction of the utorso link frame -->
      <origin xyz="-0.0026 0.0264 0.6649" rpy="0 0 3.14159"/>
    </joint>
    <joint name="rear_situational_awareness_camera_optical_frame_joint" type="fixed">
      <origin xyz="0 0 0" rpy="-1.5708 0.0 -1.5708" />
      <parent link="rear_situational_awareness_camera_link" />
      <child link="rear_situational_awareness_camera_optical_frame"/>
    </joint>
    <link name="rear_situational_awareness_camera_optical_frame"/> 

</robot>
